File: app/data/PBS_3Kmin.txt
#EXPORTTYPE:DATA SINGLE
#FILE:2024-02-15_Неизотермическая кристаллизация PBS_25-140_3-5-10-15-17-20Kmin_50mlmin.ngb-sd7
#FORMAT:NETZSCH5
#FTYPE:ANSI
#IDENTITY:PBS
#DECIMAL:POINT
#SEPARATOR:SEMICOLON
#MTYPE:DSC
#INSTRUMENT:NETZSCH DSC 204F1 Phoenix
#PROJECT:
#DATE/TIME:15.02.2024 11:16
#CORR. FILE:
#TEMPCAL:06-12-2021 13:53
#SENSITIVITY:06-12-2021 13:52
#LABORATORY:
#OPERATOR:SitnikovaV
#REMARK:
#SAMPLE:PBS
#SAMPLE MASS /mg:17,842
#MATERIAL:polymer
#REFERENCE:ПВС порошок
#REFERENCE MASS /mg:0
#TYPE OF CRUCIBLE:Concavus Al, closed
#SAMPLE CRUCIBLE MASS /mg:0
#REFERENCE CRUCIBLE MASS /mg:0
#PURGE 1 MFC:OXYGEN,252,5 ml/min
#PURGE 2 MFC:NITROGEN,250,0 ml/min
#PROTECTIVE MFC:NITROGEN,250,0 ml/min
#M.RANGE /µV:5000
#TAU-R:---
#CORR. CODE:000
#EXO:-1
#RANGE:140°C/3.0(K/min)/50°C
#SEGMENT:S3/24
#SEG. 3:140°C/3.0(K/min)/50°C

##Temp./°C;Time/min;DSC/(mW/mg);Sensit./(uV/mW)
 50.02500;40.74500;     -0.10943;3.45117
 50.52500;40.57792;     -0.10977;3.45093
 51.02500;40.41065;     -0.11006;3.45068
 51.52500;40.24338;     -0.11030;3.45043
 52.02500;40.07612;     -0.11061;3.45018
 52.52500;39.90891;     -0.11098;3.44992
 53.02500;39.74184;     -0.11136;3.44966
 53.52500;39.57494;     -0.11178;3.44940
 54.02500;39.40822;     -0.11213;3.44913
 54.52500;39.24165;     -0.11230;3.44886
 55.02500;39.07518;     -0.11270;3.44859
 55.52500;38.90878;     -0.11300;3.44832
 56.02500;38.74243;     -0.11321;3.44804
 56.52500;38.57608;     -0.11370;3.44776
 57.02500;38.40972;     -0.11377;3.44748
 57.52500;38.24326;     -0.11401;3.44719
 58.02500;38.07665;     -0.11432;3.44690
 58.52500;37.90989;     -0.11446;3.44661
 59.02500;37.74296;     -0.11500;3.44632
 59.52500;37.57590;     -0.11550;3.44602
 60.02500;37.40877;     -0.11571;3.44572
 60.52500;37.24164;     -0.11629;3.44542
 61.02500;37.07460;     -0.11711;3.44511
 61.52500;36.90778;     -0.11787;3.44480
 62.02500;36.74122;     -0.11844;3.44449
 62.52500;36.57489;     -0.11899;3.44418
 63.02500;36.40871;     -0.11978;3.44386
 63.52500;36.24255;     -0.12018;3.44354
 64.02500;36.07632;     -0.12065;3.44322
 64.52500;35.90991;     -0.12096;3.44289
 65.02500;35.74328;     -0.12149;3.44256
 65.52500;35.57640;     -0.12198;3.44223
 66.02500;35.40929;     -0.12268;3.44190
 66.52500;35.24199;     -0.12306;3.44156
 67.02500;35.07459;     -0.12370;3.44122
 67.52500;34.90715;     -0.12477;3.44088
 68.02500;34.73984;     -0.12578;3.44053
 68.52500;34.57278;     -0.12686;3.44019
 69.02500;34.40598;     -0.12770;3.43984
 69.52500;34.23950;     -0.12851;3.43948
 70.02500;34.07327;     -0.12922;3.43912
 70.52500;33.90723;     -0.13015;3.43876
 71.02500;33.74131;     -0.13070;3.43840
 71.52500;33.57541;     -0.13119;3.43804
 72.02500;33.40945;     -0.13154;3.43767
 72.52500;33.24334;     -0.13235;3.43730
 73.02500;33.07706;     -0.13277;3.43692
 73.52500;32.91056;     -0.13312;3.43655
 74.02500;32.74381;     -0.13358;3.43617
 74.52500;32.57678;     -0.13406;3.43579
 75.02500;32.40945;     -0.13472;3.43540
 75.52500;32.24184;     -0.13534;3.43501
 76.02500;32.07405;     -0.13629;3.43462
 76.52500;31.90620;     -0.13733;3.43423
 77.02500;31.73841;     -0.13894;3.43383
 77.52500;31.57084;     -0.14038;3.43343
 78.02500;31.40355;     -0.14237;3.43303
 78.52500;31.23661;     -0.14482;3.43262
 79.02500;31.07003;     -0.14771;3.43222
 79.52500;30.90377;     -0.15085;3.43181
 80.02500;30.73772;     -0.15616;3.43139
 80.52500;30.57176;     -0.16497;3.43098
 81.02500;30.40573;     -0.18114;3.43056
 81.52500;30.23958;     -0.21059;3.43014
 82.02500;30.07333;     -0.25894;3.42971
 82.52500;29.90704;     -0.32969;3.42928
 83.02500;29.74079;     -0.41857;3.42885
 83.52500;29.57456;     -0.51554;3.42842
 84.02500;29.40831;     -0.60907;3.42798
 84.52500;29.24196;     -0.68910;3.42754
 85.02500;29.07548;     -0.74775;3.42710
 85.52500;28.90889;     -0.77957;3.42666
 86.02500;28.74222;     -0.78380;3.42621
 86.52500;28.57553;     -0.76283;3.42576
 87.02500;28.40882;     -0.72021;3.42531
 87.52500;28.24209;     -0.66192;3.42485
 88.02500;28.07531;     -0.59353;3.42439
 88.52500;27.90845;     -0.52113;3.42393
 89.02500;27.74153;     -0.44954;3.42347
 89.52500;27.57455;     -0.38258;3.42300
 90.02500;27.40750;     -0.32298;3.42253
 90.52500;27.24040;     -0.27216;3.42206
 91.02500;27.07323;     -0.23050;3.42158
 91.52500;26.90602;     -0.19752;3.42111
 92.02500;26.73876;     -0.17268;3.42063
 92.52500;26.57153;     -0.15441;3.42014
 93.02500;26.40437;     -0.14129;3.41966
 93.52500;26.23733;     -0.13273;3.41917
 94.02500;26.07050;     -0.12726;3.41867
 94.52500;25.90387;     -0.12449;3.41818
 95.02500;25.73744;     -0.12322;3.41768
 95.52500;25.57120;     -0.12284;3.41718
 96.02500;25.40504;     -0.12260;3.41668
 96.52500;25.23891;     -0.12257;3.41617
 97.02500;25.07271;     -0.12240;3.41566
 97.52500;24.90637;     -0.12233;3.41515
 98.02500;24.73989;     -0.12246;3.41464
 98.52500;24.57330;     -0.12277;3.41412
 99.02500;24.40667;     -0.12290;3.41360
 99.52500;24.24003;     -0.12299;3.41308
100.02500;24.07337;     -0.12322;3.41255
100.52500;23.90668;     -0.12324;3.41202
101.02500;23.73988;     -0.12344;3.41149
101.52500;23.57296;     -0.12350;3.41096
102.02500;23.40593;     -0.12366;3.41042
102.52500;23.23881;     -0.12393;3.40988
103.02500;23.07171;     -0.12438;3.40934
103.52500;22.90473;     -0.12469;3.40880
104.02500;22.73792;     -0.12485;3.40825
104.52500;22.57126;     -0.12525;3.40770
105.02500;22.40473;     -0.12540;3.40714
105.52500;22.23827;     -0.12572;3.40659
106.02500;22.07186;     -0.12598;3.40603
106.52500;21.90542;     -0.12600;3.40547
107.02500;21.73889;     -0.12592;3.40490
107.52500;21.57222;     -0.12630;3.40434
108.02500;21.40543;     -0.12641;3.40377
108.52500;21.23852;     -0.12669;3.40320
109.02500;21.07157;     -0.12675;3.40262
109.52500;20.90461;     -0.12731;3.40204
110.02500;20.73766;     -0.12765;3.40146
110.52500;20.57082;     -0.12801;3.40088
111.02500;20.40412;     -0.12827;3.40029
111.52500;20.23758;     -0.12843;3.39970
112.02500;20.07115;     -0.12867;3.39911
112.52500;19.90475;     -0.12871;3.39852
113.02500;19.73834;     -0.12883;3.39792
113.52500;19.57192;     -0.12926;3.39732
114.02500;19.40551;     -0.12962;3.39672
114.52500;19.23909;     -0.12970;3.39611
115.02500;19.07258;     -0.12973;3.39550
115.52500;18.90597;     -0.12977;3.39489
116.02500;18.73928;     -0.13013;3.39428
116.52500;18.57258;     -0.13057;3.39366
117.02500;18.40599;     -0.13070;3.39304
117.52500;18.23952;     -0.13095;3.39242
118.02500;18.07316;     -0.13130;3.39180
118.52500;17.90689;     -0.13157;3.39117
119.02500;17.74069;     -0.13164;3.39054
119.52500;17.57455;     -0.13198;3.38991
120.02500;17.40842;     -0.13214;3.38927
120.52500;17.24225;     -0.13209;3.38863
121.02500;17.07596;     -0.13199;3.38799
121.52500;16.90951;     -0.13202;3.38735
122.02500;16.74288;     -0.13240;3.38670
122.52500;16.57611;     -0.13217;3.38605
123.02500;16.40919;     -0.13237;3.38540
123.52500;16.24222;     -0.13281;3.38475
124.02500;16.07538;     -0.13309;3.38409
124.52500;15.90877;     -0.13386;3.38343
125.02500;15.74253;     -0.13435;3.38277
125.52500;15.57663;     -0.13434;3.38210
126.02500;15.41091;     -0.13443;3.38143
126.52500;15.24522;     -0.13464;3.38076
127.02500;15.07945;     -0.13478;3.38009
127.52500;14.91348;     -0.13479;3.37941
128.02500;14.74732;     -0.13469;3.37873
128.52500;14.58102;     -0.13489;3.37805
129.02500;14.41470;     -0.13527;3.37737
129.52500;14.24850;     -0.13586;3.37668
130.02500;14.08254;     -0.13612;3.37599
130.52500;13.91684;     -0.13646;3.37530
131.02500;13.75138;     -0.13687;3.37460
131.52500;13.58618;     -0.13725;3.37391
132.02500;13.42125;     -0.13775;3.37321
132.52500;13.25669;     -0.13842;3.37250
133.02500;13.09263;     -0.13946;3.37180
133.52500;12.92922;     -0.14045;3.37109
134.02500;12.76666;     -0.14168;3.37038
134.52500;12.60527;     -0.14289;3.36966
135.02500;12.44539;     -0.14523;3.36895
135.52500;12.28749;     -0.14784;3.36823
136.02500;12.13202;     -0.15030;3.36751
136.52500;11.97935;     -0.15322;3.36678
137.02500;11.82966;     -0.15542;3.36605
137.52500;11.68262;     -0.15623;3.36533
138.02500;11.53662;     -0.15304;3.36459
138.52500;11.38723;     -0.14144;3.36386
139.02500;11.23084;     -0.11363;3.36312
139.52500;11.05294;-6.171221e-02;3.36238
140.02500;10.84059;-2.110472e-02;3.36164