File: app/data/peg/PEG_5Kmin.txt
#EXPORTTYPE:DATA SINGLE
#FILE:2024-02-15_Неизотермическая кристаллизация PEG8000_25-140_3-5-10-15-17-20Kmin_50mlmin.ngb-sd7
#FORMAT:NETZSCH5
#FTYPE:ANSI
#IDENTITY:PEG8000
#DECIMAL:POINT
#SEPARATOR:SEMICOLON
#MTYPE:DSC
#INSTRUMENT:NETZSCH DSC 204F1 Phoenix
#PROJECT:
#DATE/TIME:16.02.2024 12:03
#CORR. FILE:
#TEMPCAL:06-12-2021 13:53
#SENSITIVITY:06-12-2021 13:52
#LABORATORY:
#OPERATOR:SitnikovaV
#REMARK:
#SAMPLE:PEG8000
#SAMPLE MASS /mg:8,606
#MATERIAL:polymer
#REFERENCE:ПВС порошок
#REFERENCE MASS /mg:0
#TYPE OF CRUCIBLE:Concavus Al, closed
#SAMPLE CRUCIBLE MASS /mg:0
#REFERENCE CRUCIBLE MASS /mg:0
#PURGE 1 MFC:OXYGEN,252,5 ml/min
#PURGE 2 MFC:NITROGEN,250,0 ml/min
#PROTECTIVE MFC:NITROGEN,250,0 ml/min
#M.RANGE /µV:5000
#TAU-R:---
#CORR. CODE:000
#EXO:-1
#RANGE:100°C/5.0(K/min)/25°C
#SEGMENT:S7/24
#SEG. 7:100°C/5.0(K/min)/25°C

##Temp./°C;Time/min;DSC/(mW/mg);Sensit./(uV/mW)
 25.02200;62.49500;     -0.11671;3.45978
 25.52200;62.39500;     -0.11762;3.45968
 26.02200;62.29514;     -0.11882;3.45957
 26.52200;62.19525;     -0.11979;3.45946
 27.02200;62.09528;     -0.12045;3.45935
 27.52200;61.99523;     -0.12169;3.45924
 28.02200;61.89506;     -0.12312;3.45913
 28.52200;61.79481;     -0.12362;3.45901
 29.02200;61.69450;     -0.12539;3.45889
 29.52200;61.59417;     -0.12652;3.45876
 30.02200;61.49386;     -0.12806;3.45863
 30.52200;61.39358;     -0.12938;3.45850
 31.02200;61.29335;     -0.13133;3.45837
 31.52200;61.19318;     -0.13281;3.45824
 32.02200;61.09307;     -0.13489;3.45810
 32.52200;60.99304;     -0.13626;3.45795
 33.02200;60.89306;     -0.13845;3.45781
 33.52200;60.79312;     -0.14194;3.45766
 34.02200;60.69318;     -0.14527;3.45751
 34.52200;60.59323;     -0.15009;3.45736
 35.02200;60.49329;     -0.15831;3.45720
 35.52200;60.39335;     -0.17139;3.45704
 36.02200;60.29343;     -0.19583;3.45688
 36.52200;60.19356;     -0.23940;3.45672
 37.02200;60.09375;     -0.31941;3.45655
 37.52200;59.99405;     -0.45732;3.45638
 38.02200;59.89450;     -0.69763;3.45620
 38.52200;59.79509;     -1.13896;3.45603
 39.02200;59.69576;     -1.91928;3.45585
 39.52200;59.59643;     -2.73631;3.45567
 40.02200;59.49704;     -3.09576;3.45548
 40.52200;59.39755;     -3.16031;3.45529
 41.02200;59.29798;     -3.26827;3.45510
 41.52200;59.19834;     -3.41256;3.45491
 42.02200;59.09863;     -3.44816;3.45471
 42.52200;58.99883;     -3.31718;3.45451
 43.02200;58.89894;     -3.03616;3.45431
 43.52200;58.79897;     -2.64879;3.45411
 44.02200;58.69894;     -2.14528;3.45390
 44.52200;58.59887;     -1.65286;3.45369
 45.02200;58.49874;     -1.21573;3.45347
 45.52200;58.39856;     -0.85894;3.45326
 46.02200;58.29831;     -0.60234;3.45304
 46.52200;58.19803;     -0.41840;3.45281
 47.02200;58.09777;     -0.29390;3.45259
 47.52200;57.99754;     -0.21866;3.45236
 48.02200;57.89737;     -0.18584;3.45213
 48.52200;57.79725;     -0.17491;3.45190
 49.02200;57.69718;     -0.17271;3.45166
 49.52200;57.59715;     -0.17265;3.45142
 50.02200;57.49715;     -0.17341;3.45118
 50.52200;57.39716;     -0.17329;3.45093
 51.02200;57.29716;     -0.17361;3.45068
 51.52200;57.19715;     -0.17409;3.45043
 52.02200;57.09713;     -0.17452;3.45018
 52.52200;56.99711;     -0.17464;3.44992
 53.02200;56.89705;     -0.17463;3.44966
 53.52200;56.79695;     -0.17477;3.44940
 54.02200;56.69677;     -0.17456;3.44913
 54.52200;56.59649;     -0.17513;3.44886
 55.02200;56.49614;     -0.17546;3.44859
 55.52200;56.39576;     -0.17622;3.44832
 56.02200;56.29540;     -0.17629;3.44804
 56.52200;56.19510;     -0.17697;3.44776
 57.02200;56.09487;     -0.17729;3.44748
 57.52200;55.99470;     -0.17726;3.44719
 58.02200;55.89459;     -0.17792;3.44690
 58.52200;55.79452;     -0.17844;3.44661
 59.02200;55.69448;     -0.17892;3.44632
 59.52200;55.59449;     -0.17906;3.44602
 60.02200;55.49453;     -0.17965;3.44572
 60.52200;55.39461;     -0.18025;3.44542
 61.02200;55.29468;     -0.18057;3.44511
 61.52200;55.19474;     -0.18067;3.44481
 62.02200;55.09480;     -0.18111;3.44449
 62.52200;54.99486;     -0.18169;3.44418
 63.02200;54.89494;     -0.18214;3.44386
 63.52200;54.79509;     -0.18324;3.44354
 64.02200;54.69529;     -0.18371;3.44322
 64.52200;54.59554;     -0.18366;3.44290
 65.02200;54.49584;     -0.18407;3.44257
 65.52200;54.39615;     -0.18428;3.44224
 66.02200;54.29648;     -0.18508;3.44190
 66.52200;54.19682;     -0.18562;3.44156
 67.02200;54.09717;     -0.18555;3.44123
 67.52200;53.99754;     -0.18596;3.44088
 68.02200;53.89789;     -0.18639;3.44054
 68.52200;53.79820;     -0.18660;3.44019
 69.02200;53.69845;     -0.18695;3.43984
 69.52200;53.59862;     -0.18704;3.43948
 70.02200;53.49873;     -0.18720;3.43913
 70.52200;53.39880;     -0.18759;3.43877
 71.02200;53.29883;     -0.18786;3.43840
 71.52200;53.19884;     -0.18768;3.43804
 72.02200;53.09882;     -0.18839;3.43767
 72.52200;52.99879;     -0.18862;3.43730
 73.02200;52.89878;     -0.18890;3.43693
 73.52200;52.79880;     -0.18975;3.43655
 74.02200;52.69886;     -0.18998;3.43617
 74.52200;52.59893;     -0.19046;3.43579
 75.02200;52.49899;     -0.19115;3.43540
 75.52200;52.39903;     -0.19115;3.43501
 76.02200;52.29904;     -0.19150;3.43462
 76.52200;52.19903;     -0.19211;3.43423
 77.02200;52.09904;     -0.19224;3.43383
 77.52200;51.99906;     -0.19301;3.43343
 78.02200;51.89909;     -0.19324;3.43303
 78.52200;51.79912;     -0.19364;3.43263
 79.02200;51.69915;     -0.19406;3.43222
 79.52200;51.59920;     -0.19471;3.43181
 80.02200;51.49927;     -0.19495;3.43139
 80.52200;51.39937;     -0.19555;3.43098
 81.02200;51.29950;     -0.19614;3.43056
 81.52200;51.19971;     -0.19654;3.43014
 82.02200;51.09999;     -0.19747;3.42971
 82.52200;51.00035;     -0.19792;3.42929
 83.02200;50.90075;     -0.19902;3.42885
 83.52200;50.80118;     -0.19902;3.42842
 84.02200;50.70161;     -0.19913;3.42799
 84.52200;50.60205;     -0.19985;3.42755
 85.02200;50.50252;     -0.20086;3.42711
 85.52200;50.40303;     -0.20159;3.42666
 86.02200;50.30361;     -0.20196;3.42621
 86.52200;50.20429;     -0.20294;3.42576
 87.02200;50.10512;     -0.20439;3.42531
 87.52200;50.00613;     -0.20500;3.42486
 88.02200;49.90736;     -0.20648;3.42440
 88.52200;49.80882;     -0.20785;3.42394
 89.02200;49.71056;     -0.20928;3.42347
 89.52200;49.61263;     -0.21105;3.42300
 90.02200;49.51508;     -0.21243;3.42253
 90.52200;49.41798;     -0.21429;3.42206
 91.02200;49.32136;     -0.21599;3.42159
 91.52200;49.22530;     -0.21795;3.42111
 92.02200;49.12986;     -0.22098;3.42063
 92.52200;49.03518;     -0.22437;3.42014
 93.02200;48.94136;     -0.22762;3.41966
 93.52200;48.84853;     -0.23110;3.41917
 94.02200;48.75681;     -0.23519;3.41868
 94.52200;48.66628;     -0.23927;3.41818
 95.02200;48.57698;     -0.24341;3.41768
 95.52200;48.48889;     -0.24688;3.41718
 96.02200;48.40196;     -0.24977;3.41668
 96.52200;48.31599;     -0.25155;3.41617
 97.02200;48.23064;     -0.25062;3.41567
 97.52200;48.14521;     -0.24542;3.41515
 98.02200;48.05837;     -0.23340;3.41464
 98.52200;47.96746;     -0.20877;3.41412
 99.02200;47.86686;     -0.16508;3.41360
 99.52200;47.74567;-9.091125e-02;3.41308
100.02200;47.57450;-2.274382e-02;3.41256