File: app/data/peg/PEG_15Kmin.txt
#EXPORTTYPE:DATA SINGLE
#FILE:2024-02-15_Неизотермическая кристаллизация PEG8000_25-140_3-5-10-15-17-20Kmin_50mlmin.ngb-sd7
#FORMAT:NETZSCH5
#FTYPE:ANSI
#IDENTITY:PEG8000
#DECIMAL:POINT
#SEPARATOR:SEMICOLON
#MTYPE:DSC
#INSTRUMENT:NETZSCH DSC 204F1 Phoenix
#PROJECT:
#DATE/TIME:16.02.2024 12:03
#CORR. FILE:
#TEMPCAL:06-12-2021 13:53
#SENSITIVITY:06-12-2021 13:52
#LABORATORY:
#OPERATOR:SitnikovaV
#REMARK:
#SAMPLE:PEG8000
#SAMPLE MASS /mg:8,606
#MATERIAL:polymer
#REFERENCE:ПВС порошок
#REFERENCE MASS /mg:0
#TYPE OF CRUCIBLE:Concavus Al, closed
#SAMPLE CRUCIBLE MASS /mg:0
#REFERENCE CRUCIBLE MASS /mg:0
#PURGE 1 MFC:OXYGEN,252,5 ml/min
#PURGE 2 MFC:NITROGEN,250,0 ml/min
#PROTECTIVE MFC:NITROGEN,250,0 ml/min
#M.RANGE /µV:5000
#TAU-R:---
#CORR. CODE:000
#EXO:-1
#RANGE:100°C/15.0(K/min)/25°C
#SEGMENT:S15/24
#SEG. 15:100°C/15.0(K/min)/25°C

##Temp./°C;Time/min;DSC/(mW/mg);Sensit./(uV/mW)
25.10000;102.49500;     -0.53023;3.45976
25.60000;102.46164;     -0.57774;3.45966
26.10000;102.42837;     -0.64254;3.45956
26.60000;102.39511;     -0.72794;3.45945
27.10000;102.36187;     -0.84029;3.45934
27.60000;102.32865;     -0.98914;3.45922
28.10000;102.29545;     -1.18569;3.45911
28.60000;102.26228;     -1.44436;3.45899
29.10000;102.22913;     -1.78386;3.45887
29.60000;102.19600;     -2.22893;3.45874
30.10000;102.16287;     -2.72912;3.45861
30.60000;102.12974;     -3.14293;3.45848
31.10000;102.09661;     -3.40221;3.45835
31.60000;102.06349;     -3.61786;3.45821
32.10000;102.03039;     -3.97537;3.45807
32.60000;101.99730;     -4.43127;3.45793
33.10000;101.96422;     -4.92616;3.45779
33.60000;101.93113;     -5.44292;3.45764
34.10000;101.89801;     -5.95536;3.45749
34.60000;101.86485;     -6.39359;3.45733
35.10000;101.83164;     -6.62372;3.45718
35.60000;101.79839;     -6.71341;3.45702
36.10000;101.76509;     -6.64833;3.45686
36.60000;101.73175;     -6.44549;3.45669
37.10000;101.69839;     -6.14798;3.45652
37.60000;101.66500;     -5.76009;3.45635
38.10000;101.63158;     -5.27063;3.45618
38.60000;101.59813;     -4.69848;3.45600
39.10000;101.56467;     -4.09697;3.45582
39.60000;101.53122;     -3.51106;3.45564
40.10000;101.49777;     -2.95517;3.45545
40.60000;101.46435;     -2.44135;3.45526
41.10000;101.43094;     -1.98579;3.45507
41.60000;101.39756;     -1.59916;3.45488
42.10000;101.36420;     -1.27524;3.45468
42.60000;101.33086;     -1.02157;3.45448
43.10000;101.29754;     -0.82676;3.45428
43.60000;101.26425;     -0.69490;3.45407
44.10000;101.23097;     -0.61624;3.45386
44.60000;101.19771;     -0.57128;3.45365
45.10000;101.16447;     -0.54595;3.45344
45.60000;101.13122;     -0.53248;3.45322
46.10000;101.09797;     -0.52727;3.45300
46.60000;101.06472;     -0.52556;3.45278
47.10000;101.03147;     -0.52600;3.45255
47.60000;100.99822;     -0.52635;3.45232
48.10000;100.96497;     -0.52722;3.45209
48.60000;100.93172;     -0.52744;3.45186
49.10000;100.89848;     -0.52831;3.45162
49.60000;100.86523;     -0.52887;3.45138
50.10000;100.83199;     -0.52988;3.45114
50.60000;100.79876;     -0.53041;3.45089
51.10000;100.76554;     -0.53095;3.45064
51.60000;100.73232;     -0.53149;3.45039
52.10000;100.69909;     -0.53241;3.45014
52.60000;100.66587;     -0.53289;3.44988
53.10000;100.63265;     -0.53366;3.44962
53.60000;100.59944;     -0.53437;3.44936
54.10000;100.56623;     -0.53521;3.44909
54.60000;100.53303;     -0.53584;3.44882
55.10000;100.49983;     -0.53706;3.44855
55.60000;100.46664;     -0.53723;3.44828
56.10000;100.43345;     -0.53804;3.44800
56.60000;100.40027;     -0.53912;3.44772
57.10000;100.36708;     -0.53971;3.44743
57.60000;100.33390;     -0.54089;3.44715
58.10000;100.30072;     -0.54156;3.44686
58.60000;100.26755;     -0.54220;3.44657
59.10000;100.23439;     -0.54290;3.44627
59.60000;100.20124;     -0.54411;3.44598
60.10000;100.16809;     -0.54532;3.44568
60.60000;100.13496;     -0.54603;3.44537
61.10000;100.10183;     -0.54714;3.44507
61.60000;100.06870;     -0.54800;3.44476
62.10000;100.03559;     -0.54869;3.44445
62.60000;100.00249;     -0.55040;3.44413
63.10000; 99.96941;     -0.55147;3.44381
63.60000; 99.93634;     -0.55227;3.44349
64.10000; 99.90329;     -0.55408;3.44317
64.60000; 99.87027;     -0.55534;3.44284
65.10000; 99.83727;     -0.55688;3.44252
65.60000; 99.80431;     -0.55841;3.44218
66.10000; 99.77137;     -0.55972;3.44185
66.60000; 99.73846;     -0.56130;3.44151
67.10000; 99.70557;     -0.56297;3.44117
67.60000; 99.67272;     -0.56473;3.44083
68.10000; 99.63990;     -0.56616;3.44048
68.60000; 99.60712;     -0.56812;3.44013
69.10000; 99.57439;     -0.56990;3.43978
69.60000; 99.54170;     -0.57186;3.43943
70.10000; 99.50905;     -0.57363;3.43907
70.60000; 99.47645;     -0.57604;3.43871
71.10000; 99.44389;     -0.57794;3.43835
71.60000; 99.41140;     -0.58033;3.43798
72.10000; 99.37896;     -0.58200;3.43761
72.60000; 99.34658;     -0.58454;3.43724
73.10000; 99.31426;     -0.58687;3.43687
73.60000; 99.28200;     -0.58923;3.43649
74.10000; 99.24981;     -0.59201;3.43611
74.60000; 99.21769;     -0.59463;3.43573
75.10000; 99.18564;     -0.59746;3.43534
75.60000; 99.15368;     -0.60050;3.43495
76.10000; 99.12179;     -0.60330;3.43456
76.60000; 99.08999;     -0.60643;3.43417
77.10000; 99.05828;     -0.60992;3.43377
77.60000; 99.02666;     -0.61279;3.43337
78.10000; 98.99513;     -0.61655;3.43297
78.60000; 98.96371;     -0.62039;3.43256
79.10000; 98.93239;     -0.62401;3.43216
79.60000; 98.90118;     -0.62736;3.43174
80.10000; 98.87009;     -0.63130;3.43133
80.60000; 98.83911;     -0.63566;3.43091
81.10000; 98.80825;     -0.63961;3.43049
81.60000; 98.77752;     -0.64384;3.43007
82.10000; 98.74691;     -0.64839;3.42965
82.60000; 98.71644;     -0.65259;3.42922
83.10000; 98.68611;     -0.65730;3.42879
83.60000; 98.65593;     -0.66162;3.42835
84.10000; 98.62590;     -0.66629;3.42792
84.60000; 98.59603;     -0.67027;3.42748
85.10000; 98.56630;     -0.67463;3.42704
85.60000; 98.53672;     -0.67882;3.42659
86.10000; 98.50728;     -0.68336;3.42614
86.60000; 98.47800;     -0.68714;3.42569
87.10000; 98.44886;     -0.69090;3.42524
87.60000; 98.41986;     -0.69428;3.42478
88.10000; 98.39102;     -0.69702;3.42432
88.60000; 98.36231;     -0.70000;3.42386
89.10000; 98.33374;     -0.70176;3.42340
89.60000; 98.30530;     -0.70315;3.42293
90.10000; 98.27697;     -0.70328;3.42246
90.60000; 98.24874;     -0.70179;3.42199
91.10000; 98.22062;     -0.69997;3.42151
91.60000; 98.19256;     -0.69657;3.42103
92.10000; 98.16455;     -0.69165;3.42055
92.60000; 98.13656;     -0.68395;3.42007
93.10000; 98.10856;     -0.67436;3.41958
93.60000; 98.08048;     -0.66210;3.41909
94.10000; 98.05229;     -0.64682;3.41860
94.60000; 98.02390;     -0.62791;3.41810
95.10000; 97.99524;     -0.60553;3.41761
95.60000; 97.96619;     -0.57812;3.41711
96.10000; 97.93660;     -0.54630;3.41660
96.60000; 97.90627;     -0.50814;3.41610
97.10000; 97.87493;     -0.46348;3.41559
97.60000; 97.84214;     -0.41078;3.41507
98.10000; 97.80719;     -0.34904;3.41456
98.60000; 97.76881;     -0.27704;3.41404
99.10000; 97.72422;     -0.19323;3.41352
99.60000; 97.66506;-9.726268e-02;3.41300